<?xml version="1.0" ?>
<!-- =================================================================================== -->
<!-- |    This document was autogenerated by xacro from thief.urdf.xacro               | -->
<!-- |    EDITING THIS FILE BY HAND IS NOT RECOMMENDED                                 | -->
<!-- =================================================================================== -->
<robot name="Guard" xmlns:xacro="http://www.ros.org/wiki/xacro">
  <!-- MODELS -->
  <material name="iRobot/Green">
    <color rgba="0.0 0.6 0.0 1.0"/>
  </material>
  <material name="iRobot/Yellow">
    <color rgba="1.0 1.0 0.0 1.0"/>
  </material>
  <material name="iRobot/Blue">
    <color rgba="0.0 0.5 1.0 1.0"/>
  </material>
  <material name="iRobot/LightYellow">
    <color rgba="1.0 1.0 0.6 1.0"/>
  </material>
  <material name="iRobot/Grey">
    <color rgba="0.75 0.75 0.75 1.0"/>
  </material>
  <material name="iRobot/Black">
    <color rgba="0.0 0.0 0.0 1.0"/>
  </material>
  <material name="iRobot/Red">
    <color rgba="0.8 0.0 0.0 1.0"/>
  </material>
  <material name="iRobot/White">
    <color rgba="0.95 0.95 0.95 1.0"/>
  </material>
  <link name="base_link"/>
  <joint name="base_joint" type="fixed">
    <origin rpy="0 0 0" xyz="0 0 0.0475"/>
    <parent link="base_link"/>
    <child link="chassis"/>
  </joint>
  <link name="chassis">
    <inertial>
      <origin rpy="0 0 0" xyz="0 0 0"/>
      <mass value="10"/>
      <inertia ixx="0.2125" ixy="0.0" ixz="0.0" iyy="0.2125" iyz="0.0" izz="0.425"/>
    </inertial>
    <visual>
      <origin rpy="0 0 0" xyz="0 0 0"/>
      <geometry>
        <cylinder length="0.055" radius="0.085"/>
      </geometry>
    </visual>
    <collision>
      <origin rpy="0 0 0" xyz="0 0 0"/>
      <geometry>
        <cylinder length="0.055" radius="0.085"/>
      </geometry>
    </collision>
  </link>
  <gazebo reference="chassis">
    <material>Gazebo/Red</material>
  </gazebo>
  <joint name="left_axis_base_joint" type="fixed">
    <origin rpy="0 0 0" xyz="-0.03 0.0725 -0.015"/>
    <parent link="chassis"/>
    <child link="left_axis"/>
  </joint>
  <link name="left_axis">
    <inertial>
      <origin rpy="-1.57079632679 0 0" xyz="0 0 0"/>
      <mass value="0.001"/>
      <inertia ixx="6.25e-07" ixy="0.0" ixz="0.0" iyy="6.25e-07" iyz="0.0" izz="2.08333333333e-07"/>
    </inertial>
    <visual>
      <origin rpy="-1.57079632679 0 0" xyz="0 0 0"/>
      <geometry>
        <cylinder length="0.02" radius="0.0025"/>
      </geometry>
    </visual>
    <collision>
      <origin rpy="-1.57079632679 0 0" xyz="0 0 0"/>
      <geometry>
        <cylinder length="0.02" radius="0.0025"/>
      </geometry>
    </collision>
  </link>
  <gazebo reference="left_axis_axis">
    <gravity>true</gravity>
    <material>Gazebo/Red</material>
    <mu1>0.8</mu1>
    <mu2>0.8</mu2>
  </gazebo>
  <joint name="left_wheel_rot_joint" type="continuous">
    <origin rpy="0 0 0" xyz="0 0 0"/>
    <axis xyz="0 1 0"/>
    <limit effort="100" velocity="100"/>
    <joint_properties damping="0.0" friction="0.0"/>
    <parent link="left_axis"/>
    <child link="left_wheel_link"/>
  </joint>
  <link name="left_wheel_link">
    <inertial>
      <origin rpy="-1.57079632679 0 0" xyz="0 0.01 0"/>
      <mass value="0.015"/>
      <inertia ixx="0.000121875" ixy="0.0" ixz="0.0" iyy="0.000121875" iyz="0.0" izz="4.0625e-05"/>
    </inertial>
    <visual>
      <origin rpy="-1.57079632679 0 0" xyz="0 0 0"/>
      <geometry>
        <cylinder length="0.025" radius="0.0325"/>
      </geometry>
      <material name="iRobot/LightYellow"/>
    </visual>
    <collision>
      <origin rpy="-1.57079632679 0 0" xyz="0 0 0"/>
      <geometry>
        <cylinder length="0.025" radius="0.0325"/>
      </geometry>
    </collision>
  </link>
  <gazebo reference="left_wheel_link">
    <material>Gazebo/Yellow</material>
  </gazebo>
  <gazebo reference="left_wheel_link">
    <gravity>true</gravity>
    <material>Gazebo/Grey</material>
    <mu1>50</mu1>
    <mu2>10</mu2>
    <kp>10000000</kp>
    <kd>1</kd>
    <fdir1>1 0 0</fdir1>
    <minDepth>0.0001</minDepth>
    <maxContacts>1</maxContacts>
  </gazebo>
  <joint name="right_axis_base_joint" type="fixed">
    <origin rpy="0 0 0" xyz="-0.03 -0.0725 -0.015"/>
    <parent link="chassis"/>
    <child link="right_axis"/>
  </joint>
  <link name="right_axis">
    <inertial>
      <origin rpy="-1.57079632679 0 0" xyz="0 0 0"/>
      <mass value="0.001"/>
      <inertia ixx="6.25e-07" ixy="0.0" ixz="0.0" iyy="6.25e-07" iyz="0.0" izz="2.08333333333e-07"/>
    </inertial>
    <visual>
      <origin rpy="-1.57079632679 0 0" xyz="0 0 0"/>
      <geometry>
        <cylinder length="0.02" radius="0.0025"/>
      </geometry>
    </visual>
    <collision>
      <origin rpy="-1.57079632679 0 0" xyz="0 0 0"/>
      <geometry>
        <cylinder length="0.02" radius="0.0025"/>
      </geometry>
    </collision>
  </link>
  <gazebo reference="right_axis_axis">
    <gravity>true</gravity>
    <material>Gazebo/Red</material>
    <mu1>0.8</mu1>
    <mu2>0.8</mu2>
  </gazebo>
  <joint name="right_wheel_rot_joint" type="continuous">
    <origin rpy="0 0 0" xyz="0 0 0"/>
    <axis xyz="0 1 0"/>
    <limit effort="100" velocity="100"/>
    <joint_properties damping="0.0" friction="0.0"/>
    <parent link="right_axis"/>
    <child link="right_wheel_link"/>
  </joint>
  <link name="right_wheel_link">
    <inertial>
      <origin rpy="-1.57079632679 0 0" xyz="0 0.01 0"/>
      <mass value="0.015"/>
      <inertia ixx="0.000121875" ixy="0.0" ixz="0.0" iyy="0.000121875" iyz="0.0" izz="4.0625e-05"/>
    </inertial>
    <visual>
      <origin rpy="-1.57079632679 0 0" xyz="0 0 0"/>
      <geometry>
        <cylinder length="0.025" radius="0.0325"/>
      </geometry>
      <material name="iRobot/LightYellow"/>
    </visual>
    <collision>
      <origin rpy="-1.57079632679 0 0" xyz="0 0 0"/>
      <geometry>
        <cylinder length="0.025" radius="0.0325"/>
      </geometry>
    </collision>
  </link>
  <gazebo reference="right_wheel_link">
    <material>Gazebo/Yellow</material>
  </gazebo>
  <gazebo reference="right_wheel_link">
    <gravity>true</gravity>
    <material>Gazebo/Grey</material>
    <mu1>50</mu1>
    <mu2>10</mu2>
    <kp>10000000</kp>
    <kd>1</kd>
    <fdir1>1 0 0</fdir1>
    <minDepth>0.0001</minDepth>
    <maxContacts>1</maxContacts>
  </gazebo>
  <joint name="sphere_joint" type="revolute">
    <origin rpy="0 0 0" xyz="0.075 0 -0.0375"/>
    <axis xyz="0 0 1"/>
    <limit effort="100" lower="0" upper="0" velocity="100"/>
    <parent link="chassis"/>
    <child link="sphere"/>
  </joint>
  <link name="sphere">
    <inertial>
      <origin rpy="0 0 0" xyz="0 0 0"/>
      <mass value="0.03"/>
      <inertia ixx="0.00012" ixy="0.0" ixz="0.0" iyy="0.00012" iyz="0.0" izz="0.00012"/>
    </inertial>
    <visual>
      <origin rpy="0 0 0" xyz="0 0 0"/>
      <geometry>
        <sphere radius="0.01"/>
      </geometry>
    </visual>
    <collision>
      <origin rpy="0 0 0" xyz="0 0 0"/>
      <geometry>
        <sphere radius="0.01"/>
      </geometry>
    </collision>
  </link>
  <joint name="front_marker_joint" type="fixed">
    <origin rpy="0 0 0" xyz="0.075 0 0.0275"/>
    <parent link="chassis"/>
    <child link="front_marker"/>
  </joint>
  <link name="front_marker">
    <inertial>
      <origin rpy="0 0 0" xyz="0 0 0"/>
      <mass value="0.001"/>
      <inertia ixx="0.00001" ixy="0.0" ixz="0.0" iyy="0.00001" iyz="0.0" izz="0.00001"/>
    </inertial>
    <visual>
      <origin rpy="0 0 0" xyz="0 0 0"/>
      <geometry>
        <cylinder length="0.01" radius="0.005"/>
      </geometry>
    </visual>
    <collision>
      <origin rpy="0 0 0" xyz="0 0 0"/>
      <geometry>
        <cylinder length="0.01" radius="0.005"/>
      </geometry>
    </collision>
  </link>
  <joint name="imu_sensor_joint" type="fixed">
    <axis xyz="0 0 1"/>
    <origin rpy="0 0 0" xyz="-0.05 0 0.0275"/>
    <parent link="chassis"/>
    <child link="imu_sensor_link"/>
  </joint>
  <link name="imu_sensor_link">
    <collision>
      <origin rpy="0 0 0" xyz="0 0 0"/>
      <geometry>
        <box size="0.03 0.03 0.03"/>
      </geometry>
    </collision>
    <visual>
      <origin rpy="0 0 0" xyz="0 0 0"/>
      <geometry>
        <box size="0.03 0.03 0.03"/>
      </geometry>
    </visual>
    <inertial>
      <mass value="0.001"/>
      <origin rpy="0 0 0" xyz="0 0 0"/>
      <inertia ixx="0.00000015" ixy="0" ixz="0" iyy="0.00000015" iyz="0" izz="0.00000015"/>
    </inertial>
  </link>
  <gazebo reference="imu_sensor_link">
    <material>Gazebo/Orange</material>
    <gravity>true</gravity>
    <sensor name="imu_sensor" type="imu">
      <always_on>1</always_on>
      <update_rate>1000</update_rate>
      <visualize>1</visualize>
      <topic>__default_topic__</topic>
      <imu/>
      <plugin filename="libgazebo_ros_imu_sensor.so" name="imu_plugin">
        <topicName>imu_data</topicName>
        <bodyName>imu_sensor_link</bodyName>
        <updateRateHZ>1.0</updateRateHZ>
        <gaussianNoise>0.0</gaussianNoise>
        <xyzOffset>0 0 0</xyzOffset>
        <rpyOffset>0 0 0</rpyOffset>
      </plugin>
      <pose>0 0 0 0 0 0</pose>
    </sensor>
  </gazebo>
  <gazebo reference="base_link">
    </gazebo>
  <gazebo reference="ground">
    </gazebo>
  <gazebo reference="sphere">
    <gravity>true</gravity>
    <material>Gazebo/Grey</material>
    <mu1>0</mu1>
    <mu2>0</mu2>
    <kp>10000000</kp>
    <kd>1</kd>
    <fdir1>1 0 0</fdir1>
    <minDepth>0.0001</minDepth>
    <maxContacts>1</maxContacts>
  </gazebo>
  <gazebo reference="chassis">
    <gravity>true</gravity>
    <material>Gazebo/Yellow</material>
  </gazebo>
  <gazebo>
    <static>false</static>
    <plugin filename="libgazebo_ros_diff_drive.so" name="differential_drive_controller">
      <rosDebugLevel>Debug</rosDebugLevel>
      <publishWheelTF>false</publishWheelTF>
      <publishWheelJointState>true</publishWheelJointState>
      <alwaysOn>true</alwaysOn>
      <leftJoint>left_wheel_rot_joint</leftJoint>
      <rightJoint>right_wheel_rot_joint</rightJoint>
      <wheelSeparation>0.14</wheelSeparation>
      <wheelDiameter>0.065</wheelDiameter>
      <torque>10</torque>
      <wheelAcceleration>1.8</wheelAcceleration>
      <commandTopic>cmd_vel</commandTopic>
      <odometryTopic>odom</odometryTopic>
      <odometryFrame>odom</odometryFrame>
      <odometrySource>encoder</odometrySource>
      <robotBaseFrame>base_link</robotBaseFrame>
      <updateRate>10.0</updateRate>
    </plugin>
    <plugin filename="libgazebo_ros_joint_state_publisher.so" name="joint_state_publisher">
      <jointName>left_wheel_rot_joint, right_wheel_rot_joint</jointName>
      <updateRate>10.0</updateRate>
      <alwaysOn>true</alwaysOn>
    </plugin>
  </gazebo>
</robot>
